Workbook

Sheet Persamaan Total
A1: Tahun | B1: Semester | C1: APSU (Luas areal padi sawah di Sumatera Utara ) | D1: HGSU/HFSU (Harga gabah di tingkat petani Sumatera Utara (Rp/kg) dideflasi dengan indeks harga pedagang besar Indonesia (2010=100 untuk semua pendeflasian)/Harga pupuk kombinasi di Sumatera Utara (Rp/kg) dideflasi dengan indeks harga umum Indonesia | G1: AISU (Luas areal sawah beririgasi di Sumatera Utara (1000 ha)) | H1: CHSU (Jumlah curah hujan rata-rata di Sumatera Utara (mm/tahun)) | I1: YISU (Produktifitas padi sawah di Sumatera Utara (ton/ha)) | J1: APSU_t-1 (Luas areal padi sawah di Sumatera Utara (1000 ha) Bedakala satu tahun dari tahun t | K1: JPSU(Penggunaan pupuk di Sumatera Utara (Kg/Ha)) | L1: ATSU ( Proporsi areal sawah intensifikasi di Sumatera Utara (%) | M1: jpsu_t-1 (Penggunaan pupuk di Sumatera Utara (Kg/Ha) Bedakala satu tahun dari tahun t | N1: PSSU Produksi padi sawah di Sumatera Utara (1000 ton) | O1: APSU (Luas areal padi sawah di Sumatera Utara (1000 ha) | P1: APSU_YISU (Luas areal padi sawah di Sumatera Utara (1000 ha)*Produktifitas padi sawah di Sumatera Utara (ton/ha) | Q1: TPSU (Total produksi padi Sumatera Utara (1000 ton) | R1: PLSU (Produksi padi ladang di Sumatera Utara (1000 ton) | S1: TPBSU (Total produksi beras Sumatera Utara (1000 ton) | T1: K(Faktor konversi dari padi/gabah menjadi beras) | U1: TPSU(Total produksi padi Sumatera Utara (1000 ton) | V1: BSPI (Harga eceran beras di pasar domestik (Rp/kg) dideflasi dengan) | W1: P (Proporsi beras untuk benih, penggunaan lain dan susut (%)) | X1: TPBI (Total produksi beras nasional (1000 ton)) | Y1: STBI(Jumlah stok beras nasional akhir tahun di Bulog (1000 ton) | Z1: HBDI(Harga beras tingkat konsumen domestik secara nasional (Rp/kg) dideflasi dengan indeks harga pedagang besar Indonesia) | AA1: LSBI(Jumlah pelepasan stok beras Bulog untuk operasi pasar (1000 ton) | AB1: ASBI (Jumlah pengadaan beras dari dalam negeri untuk stok Bulog (1000 ton) | AC1: IMBI(Jumlah impor beras Indonesia (1000 ton) | AD1: INRG(Tingkat bunga riil pinjaman Bulog (%) yaitu tingkat bunga nominal dikurangi lanju inflasi | AE1: MPBI(Marjin pemasaran beras domestik pada tahun t (Rp/kg) dideflasi dengan indeks harga pedagang besar Indonesia) | AF1: STBI_T-1 (Jumlah stok beras nasional akhir tahun di Bulog (1000 ton) Bedakala satu tahun dari tahun t | AG1: QSBI(Total penawaran beras di pasar domestik (1000 ton) | AH1: TPBI(Total produksi beras nasional (1000 ton) | AI1: BSPI(Harga eceran beras di pasar domestik (Rp/kg) dideflasi dengan indeks harga pedagang besar Indonesia) | AJ1: EXBI(Jumlah ekspor beras Indonesia(1000 ton) | AK1: KOBI(Jumlah konsumsi beras untuk pangan (1000 ton) | AL1: HJGN | AM1: GDPI(Pendapatan riil per kapita penduduk Indonesia (Rp juta/kapita) dengan tahun dasar 1990=100) | AN1: POPI(Jumlah total penduduk Indonesia (1.000.000 orang) | AO1: RKPD(Rasio penduduk perkotaan dan pedesaan (orang)) | AP1: LOGt | AQ1: KOBI-t(Jumlah konsumsi beras untuk pangan (1000 ton) Bedakala satu tahun dari tahun t | AR1: IHBI(Nilai intervensi harga eceran beras di pasar domestik (Rp/kg) dideflasi dengan indeks harga pedagang besar Indonesia) | AS1: HIMI*ECRI (Harga impor beras Indonesia (US $/kg) dideflasi dengan indeks harga pedagang besar Indonesia*Nilai tukar rupiah terhadap dollar USA (Rp/US $) dideflasi dengan rasio indeks harga konsumen Indonesia dan USA) | AV1: TPBI-TPBI_t (Total produksi beras nasional (1000 ton)-Total produksi beras nasional (1000 ton) Tahun t) | AW1: QSBI_KOBI(Total penawaran beras di pasar domestik (1000 ton) Jumlah konsumsi beras untuk pangan (1000 ton) | AZ1: HGBI | BA1: HBDI_t Harga beras tingkat konsumen domestik secara nasional (Rp/kg) dideflasi dengan indeks harga pedagang besar Indonesia Tahun t | BB1: HESU (Harga eceran beras di wilayah Sumatera Utara (Rp/kg) dideflasi dengan indeks harga pedagang besar Indonesia) | BC1: HGSU (Harga gabah di tingkat petani Sumatera Utara (Rp/kg) dideflasi dengan indeks harga pedagang besar Indonesia (2010=100 untuk semua pendeflasian) | BD1: T(Peubah kecenderungan waktu) | BE1: HESU_T (Harga gabah di tingkat petani Sumatera Utara (Rp/kg) dideflasi dengan indeks harga pedagang besar Indonesia (2010=100 untuk semua pendeflasian) Peubah kecenderungan waktu | BF1: MPBI (Marjin pemasaran beras domestik pada tahun t (Rp/kg) dideflasi dengan indeks harga pedagang besar Indonesia) | BG1: MPSU(Nilai marjin pemasaran beras di wilayah Sumatera Utara (Rp/Kg) dideflasi dengan indeks harga pedagang besar Indonesia) | BH1: MPSS (Nilai marjin pemasaran beras di pulau Sumatera selain Sumatera Utara (Rp/Kg) dideflasi dengan indeks harga pedagang besar Indonesia) | BI1: HESS (Harga eceran beras di wilayah Sumatera selain Sumatera Utara (Rp/kg) dideflasi dengan indeks harga pedagang besar Indonesia) | BJ1: HGBI (Harga gabah di tingkat petani secara nasional) | BK1: HDGB | BL1: MPBI (Marjin Pemasaran Beras Domestik Pada Tahun t (Rp/kg) dideflasi dengan indeks harga pedagang besar Indonesia ) | BM1: TPPI | BN1: HEPS | BO1: PSSU+PLSU (Produksi padi sawah di Sumatera Utara (1000 ton)+ Produksi padi ladang di Sumatera Utara (1000 ton) | BR1: ASBI/(TPPIt-TPPIt-1 (Jumlah Pengadaan Beras Dari Dalam Negeri Untuk Stok Bulog (1000 ton) | BV1: T (Peubah kecenderungan waktu) | BW1: MPSS (Nilai marjin pemasaran beras di pulau Sumatera selain Sumatera Utara (Rp/Kg) dideflasi dengan indeks harga pedagang besar Indonesia) | BX1: PSSS+PLSS (Produksi padi sawah selain Sumatera Utara (1000 ton)+Produksi padi ladang selain Sumatera Utara (1000 ton) | CA1: HGSS (Harga gabah di tingkat petani selain Sumatera Utara (Rp/kg) dideflasi dengan indeks harga pedagang besar Indonesia (2010=100 untuk semua pendeflasian) | CB1: PESU (Pendapatan usahatani padi sawah di Sumatera Utara (Rp 1000/Ha) dideflasi dengan indeks harga pedagang besar Indonesia) | CC1: BUSU (Biaya upah tenaga kerja usahatani di Sumatera Utara (Rp 1000/Ha) dideflasi dengan indeks harga pedagang besar Indonesia) | CD1: BKSU (Biaya pestisida untuk usahatani padi di Sumatera Utara (Rp 1000/Ha) dideflasi dengan indeks harga pedagang besar Indonesia) | CE1: BLSU (Biaya lainnya untuk usahatani padi di Sumatera Utara (Rp 1000/Ha) dideflasi dengan indeks harga pedagang besar Indonesia) | CF1: PESS (Pendapatan usahatani padi sawah di Sumatera selain Sumatera Utara (Rp 1000/Ha) dideflasi dengan indeks harga pedagang besar Indonesia) | CG1: YISS (Produktifitas padi sawah selain Sumatera Utara (ton/ha) | CH1: HFSS (Harga pupuk kombinasi selain Sumatera Utara (Rp/kg) dideflasi dengan indeks harga umum Indonesia | CI1: JPSS (Penggunaan pupuk selain Sumatera Utara (Kg/Ha) | CJ1: BUSS (Biaya upah tenaga kerja usahatani di Pulau Sumatera selain Sumatera Utara (Rp 1000/Ha) dideflasi dengan indeks harga pedagang besar Indonesia) | CK1: BKSS (Biaya pestisida untuk usahatani padi di Pulau Sumatera selain Sumatera Utara (Rp 1000/Ha) dideflasi dengan indeks harga pedagang besar Indonesia) | CL1: BLSS (Biaya lainnya untuk usahatani padi di Pulau Sumatera selain Sumatera Utara (Rp 1000/Ha) dideflasi dengan indeks harga pedagang besar Indonesia) | CM1: STBIt-1 | CN1: KOBI_STBI | CO1: IMBIt-1 | CP1: HMBW | CQ1: HIMIt-1 | CR1: ANSU (Nilai Akses Pangan di Sumatera Utara) | CS1: PPSU (Preferensi terhadap Jenis Pangan dan Pendidikan di Sumatera Utara) | CT1: KBSU (Kondisi jumlah kasus konflik sosial-politik ditambah jumlah fenomena bencana alam di Sumatera Utara (jumlah kejadian pertahun) | CU1: KKSU (Kesempatan Kerja di Sumatera Utara (orang)) | CV1: PKSS (Pendapatan masyarakat perkapita di Pulau Sumatera selain Sumatera Utara (Rp) | CW1: PJSU (Panjang jalan (provinsi ditambah kabupaten/kota) di Sumatera Utara (km) | CX1: ANSUt-1 | CY1: ANSS (Nilai Akses Pangan di Sumatera Utara di Pulau Sumatera selain Sumatera Utara) | CZ1: PPSS (Preferensi terhadap Jenis Pangan dan Pendidikan di Pulau Sumatera selain Sumatera Utara) | DA1: KBSS (Kondisi jumlah kasus konflik sosial-politik ditambah jumlah fenomena bencana alam di Pulau Sumatera selain Sumatera Utara(jumlah kejadian pertahun) | DB1: KKSS (Kesempatan Kerja di Pulau Sumatera selain Sumatera Utara (orang) | DC1: PKSS (Pendapatan masyarakat perkapita di Pulau Sumatera selain Sumatera Utara (Rp)) | DD1: PJSS (Panjang jalan (provinsi ditambah kabupaten/kota) di Pulau Sumatera selain Sumatera Utara (km) | DE1: PYSU (Nilai penyerapan pangan di Sumatera Utara ) | DF1: KESU (Total konsumsi energi di Sumatera Utara ) | DG1: SKSS (Sanitasi dan Akses Ketersediaan Air Bersih di Sumatera selain Sumatera Utara (unit)) | DH1: IBSU (Nilai pengetahuan Ibu Rumah Tangga tentang pola makan dan pola asuh kesehatan di Sumatera Utara(unit) | DI1: PYSUt-1 | DJ1: PYSS (Nilai penyerapan pangan di Sumatera selain Sumatera Utara) | DK1: KESS (Total konsumsi energi di Pulau Sulawesi selain Sumatera Utara) | DL1: KGSS (Kecukupan gizi di Sumatera selain Sumatera Utara (%) | DM1: FKSS (Jumlah Fasilitas Kesehatan di Sumatera selain Sumatera Utara (unit)) | DN1: SKSS (Sanitasi dan Akses Ketersediaan Air Bersih di Sumatera selain Sumatera Utara (unit) | DO1: IBSS (Nilai pengetahuan Ibu Rumah Tangga tentang pola makan dan pola asuh kesehatan di Sumatera selain Sumatera Utara (unit) | DP1: PYSSt
D2: HGSU | E2: HFSU | F2: HGSU/HFSU | AS2: HIMI | AT2: ECRI | AW2: QSBI | AX2: KOBI | AY2: QSBI_KOBI | BO2: PSSU | BP2: PLSU | BQ2: PSSU+PLSU | BR2: ASBI | BS2: TPPI | BT2: TPPIt-1 | BX2: PSSS | BY2: PLSS | DJ2: 0 | DK2: 0 | DL2: 0 | DM2: 0 | DN2: 0 | DO2: 0 | DP2: 0
A3: 2000 | B3: 1 | C3: 375.798 | D3: 1890 | E3: 1050 | F3: 1.8 | G3: 61.811 | H3: 2249 | I3: 31.33 | J3: 371848 | K3: 129 | L3: 2.64 | M3: 131 | N3: 11773.751 | O3: 375.798 | P3: 11773.751 | Q3: 50768.751 | R3: 38995 | S3: 6000.8664 | T3: 0.1182 | U3: 50768.751 | V3: 47287.097 | W3: 0.0024 | X3: 19702957 | Y3: 922.227 | Z3: 7081 | AA3: 1526.345 | AB3: 758.726 | AC3: 1171.665 | AD3: 0.058 | AE3: 755.7708 | AF3: 912947 | AG3: 23248.754 | AH3: 19702957 | AI3: 47287.097 | AJ3: 758726 | AK3: 27275.254 | AL3: 4347 | AM3: 7081 | AN3: 229.16128 | AO3: 43.812323 | AP3: 3.30103 | AQ3: 26402.445 | AR3: 363.5 | AS3: 1500 | AT3: 8719 | AU3: 13078500 | AV3: 745783.06 | AW3: 23248.754 | AX3: 27275.254 | AY3: -4026.5002 | AZ3: 2073 | BA3: 5753 | BB3: 6394 | BC3: 1890 | BD3: 2000 | BE3: 5753 | BF3: 755.7708 | BG3: 687 | BH3: 687 | BI3: 6394 | BJ3: 2073 | BK3: 1406 | BL3: 755.7708 | BM3: 1483290 | BN3: 1984 | BO3: 11773.751 | BP3: 38995 | BQ3: 50768.751 | BR3: 758.726 | BS3: 1483290 | BT3: 1397439 | BU3: 0.0088377072 | BV3: 2000 | BW3: 687 | BX3: 11773.751 | BY3: 38995 | BZ3: 50768.751 | CA3: 1948.59 | CB3: 11778.637 | CC3: 1816.302 | CD3: 22000 | CE3: 258531 | CF3: 11566621 | CG3: 32.62 | CH3: 604489 | CI3: 140 | CJ3: 1816302 | CK3: 22000 | CL3: 258531 | CM3: 912947 | CN3: -885671.75 | CO3: 1147060 | CP3: 0 | CQ3: 1463 | CR3: 59.86 | CS3: 69.75 | CT3: 500 | CU3: 90.54 | CV3: 2554 | CW3: 23514.57 | CX3: 59.37 | CY3: 59.86 | CZ3: 69.75 | DA3: 500 | DB3: 90.54 | DC3: 2554 | DD3: 23514.57 | DE3: 105.65 | DF3: 580.33 | DG3: 66.85 | DH3: 67.56 | DI3: 100.32 | DJ3: 105.65 | DK3: 580.33 | DL3: 61.811 | DM3: 2249 | DN3: 66.85 | DO3: 67.56 | DP3: 100.32
B4: 2 | C4: 377.773 | D4: 1984.5 | E4: 1075 | F4: 1.845 | G4: 66.429 | H4: 1951.5 | I4: 33.465 | J4: 373823 | K4: 128 | L4: 2.685 | M4: 130 | N4: 12646.39 | O4: 377.773 | P4: 12646.39 | Q4: 84734.89 | R4: 72088.5 | S4: 9962.2485 | T4: 0.11775 | U4: 84734.89 | V4: 49325.192 | W4: 0.00245 | X4: 20124136 | Y4: 942.443 | Z4: 7132 | AA4: 1630.414 | AB4: 764.503 | AC4: 1204.452 | AD4: 0.056 | AE4: 758.58255 | AF4: 917587 | AG4: 23657.893 | AH4: 20124136 | AI4: 49325.192 | AJ4: 764503 | AK4: 27553.573 | AL4: 4564.35 | AM4: 7132 | AN4: 229.86451 | AO4: 44.100854 | AP4: 3.3011385 | AQ4: 26838.85 | AR4: 365.25 | AS4: 1600 | AT4: 8738.5 | AU4: 13983550 | AV4: 1211088.8 | AW4: 23657.893 | AX4: 27553.573 | AY4: -3895.6797 | AZ4: 2181.5 | BA4: 6073.5 | BB4: 6442.5 | BC4: 1984.5 | BD4: 2000 | BE4: 6073.5 | BF4: 758.58255 | BG4: 689.5 | BH4: 689.5 | BI4: 6442.5 | BJ4: 2181.5 | BK4: 1636.5 | BL4: 758.58255 | BM4: 1579179 | BN4: 2083 | BO4: 12646.39 | BP4: 72088.5 | BQ4: 84734.89 | BR4: 764.503 | BS4: 1579179 | BT4: 1440364.5 | BU4: 0.0064271131 | BV4: 2000 | BW4: 689.5 | BX4: 12646.39 | BY4: 72088.5 | BZ4: 84734.89 | CA4: 2035.6245 | CB4: 11967.047 | CC4: 1843.425 | CD4: 22750 | CE4: 261169 | CF4: 12335102 | CG4: 34.255 | CH4: 626541 | CI4: 135 | CJ4: 1843425 | CK4: 22750 | CL4: 261169 | CM4: 917587 | CN4: -890033.43 | CO4: 1159362.5 | CP4: 0 | CQ4: 1481.5 | CR4: 59.81 | CS4: 69.645 | CT4: 501 | CU4: 90.44 | CV4: 2591 | CW4: 24030.025 | CX4: 59.615 | CY4: 59.81 | CZ4: 69.645 | DA4: 501 | DB4: 90.44 | DC4: 2591 | DD4: 24030.025 | DE4: 102.65 | DF4: 600.17 | DG4: 66.98 | DH4: 67.72 | DI4: 102.985 | DJ4: 102.65 | DK4: 600.17 | DL4: 66.429 | DM4: 1951.5 | DN4: 66.98 | DO4: 67.72 | DP4: 102.985
A5: 2001 | B5: 1 | C5: 379.748 | D5: 2079 | E5: 1100 | F5: 1.89 | G5: 71.047 | H5: 1654 | I5: 35.6 | J5: 375798 | K5: 127 | L5: 2.73 | M5: 129 | N5: 13519.029 | O5: 379.748 | P5: 13519.029 | Q5: 118701.03 | R5: 105182 | S5: 13923.631 | T5: 0.1173 | U5: 118701.03 | V5: 51363.287 | W5: 0.0025 | X5: 20545315 | Y5: 962.659 | Z5: 7183 | AA5: 1734.483 | AB5: 770.28 | AC5: 1237.239 | AD5: 0.054 | AE5: 761.3943 | AF5: 922227 | AG5: 24067.033 | AH5: 20545315 | AI5: 51363.287 | AJ5: 770280 | AK5: 27831.892 | AL5: 4781.7 | AM5: 7183 | AN5: 230.56774 | AO5: 44.389385 | AP5: 3.3012471 | AQ5: 27275.254 | AR5: 367 | AS5: 1700 | AT5: 8758 | AU5: 14888600 | AV5: 1676394.5 | AW5: 24067.033 | AX5: 27831.892 | AY5: -3764.8591 | AZ5: 2290 | BA5: 6394 | BB5: 6491 | BC5: 2079 | BD5: 2001 | BE5: 6394 | BF5: 761.3943 | BG5: 692 | BH5: 692 | BI5: 6491 | BJ5: 2290 | BK5: 1867 | BL5: 761.3943 | BM5: 1675068 | BN5: 2182 | BO5: 13519.029 | BP5: 105182 | BQ5: 118701.03 | BR5: 770.28 | BS5: 1675068 | BT5: 1483290 | BU5: 0.0040165191 | BV5: 2001 | BW5: 692 | BX5: 13519.029 | BY5: 105182 | BZ5: 118701.03 | CA5: 2122.659 | CB5: 12155.457 | CC5: 1870.548 | CD5: 23500 | CE5: 263807 | CF5: 13103582 | CG5: 35.89 | CH5: 648593 | CI5: 130 | CJ5: 1870548 | CK5: 23500 | CL5: 263807 | CM5: 922227 | CN5: -894395.11 | CO5: 1171665 | CP5: 0 | CQ5: 1500 | CR5: 59.76 | CS5: 69.54 | CT5: 502 | CU5: 90.34 | CV5: 2628 | CW5: 24545.48 | CX5: 59.86 | CY5: 59.76 | CZ5: 69.54 | DA5: 502 | DB5: 90.34 | DC5: 2628 | DD5: 24545.48 | DE5: 99.65 | DF5: 620.01 | DG5: 67.11 | DH5: 67.88 | DI5: 105.65 | DJ5: 99.65 | DK5: 620.01 | DL5: 71.047 | DM5: 1654 | DN5: 67.11 | DO5: 67.88 | DP5: 105.65
B6: 2 | C6: 399.448 | D6: 2146.5 | E6: 1125 | F6: 1.9076087 | G6: 78.323 | H6: 2060.5 | I6: 37.19 | J6: 377773 | K6: 128 | L6: 2.8 | M6: 128 | N6: 14886.794 | O6: 399.448 | P6: 14886.794 | Q6: 107577.79 | R6: 92691 | S6: 13052.921 | T6: 0.1218 | U6: 107577.79 | V6: 53207.521 | W6: 0.0025 | X6: 21283008 | Y6: 968.505 | Z6: 7184.5 | AA6: 1745.0165 | AB6: 778.14 | AC6: 1271.861 | AD6: 0.0535 | AE6: 795.59265 | AF6: 942443 | AG6: 24312.615 | AH6: 21283008 | AI6: 53207.521 | AJ6: 778140 | AK6: 28058.167 | AL6: 4936.95 | AM6: 7184.5 | AN6: 231.27529 | AO6: 44.681716 | AP6: 3.3013556 | AQ6: 27553.573 | AR6: 348.5 | AS6: 1750 | AT6: 8777 | AU6: 15360700 | AV6: 1079127.8 | AW6: 24312.615 | AX6: 28058.167 | AY6: -3745.5526 | AZ6: 2303 | BA6: 6442.5 | BB6: 6530.5 | BC6: 2146.5 | BD6: 2001 | BE6: 6442.5 | BF6: 795.59265 | BG6: 654 | BH6: 654 | BI6: 6530.5 | BJ6: 2303 | BK6: 1824 | BL6: 795.59265 | BM6: 1730833 | BN6: 2253 | BO6: 14886.794 | BP6: 92691 | BQ6: 107577.79 | BR6: 778.14 | BS6: 1730833 | BT6: 1579179 | BU6: 0.0055319751 | BV6: 2001 | BW6: 654 | BX6: 14886.794 | BY6: 92691 | BZ6: 107577.79 | CA6: 2248.0335 | CB6: 12356.374 | CC6: 1900.469 | CD6: 24250 | CE6: 264403 | CF6: 12905780 | CG6: 36.48 | CH6: 674508.5 | CI6: 132 | CJ6: 1900469 | CK6: 24250 | CL6: 264403 | CM6: 942443 | CN6: -914384.83 | CO6: 1204452 | CP6: 0 | CQ6: 1600 | CR6: 58.7 | CS6: 69.645 | CT6: 510 | CU6: 90.56 | CV6: 2678.5 | CW6: 24925.05 | CX6: 59.81 | CY6: 58.7 | CZ6: 69.645 | DA6: 510 | DB6: 90.56 | DC6: 2678.5 | DD6: 24925.05 | DE6: 100.65 | DF6: 641.205 | DG6: 66.985 | DH6: 68.04 | DI6: 102.65 | DJ6: 100.65 | DK6: 641.205 | DL6: 78.323 | DM6: 2060.5 | DN6: 66.985 | DO6: 68.04 | DP6: 102.65
A7: 2002 | B7: 1 | C7: 419.148 | D7: 2214 | E7: 1150 | F7: 1.9252174 | G7: 85.599 | H7: 2467 | I7: 38.78 | J7: 379748 | K7: 129 | L7: 2.87 | M7: 127 | N7: 16254.559 | O7: 419.148 | P7: 16254.559 | Q7: 96454.559 | R7: 80200 | S7: 12182.211 | T7: 0.1263 | U7: 96454.559 | V7: 55051.755 | W7: 0.0025 | X7: 22020702 | Y7: 974.351 | Z7: 7186 | AA7: 1755.55 | AB7: 786 | AC7: 1306.483 | AD7: 0.053 | AE7: 829.791 | AF7: 962659 | AG7: 24558.197 | AH7: 22020702 | AI7: 55051.755 | AJ7: 786000 | AK7: 28284.443 | AL7: 5092.2 | AM7: 7186 | AN7: 231.98284 | AO7: 44.974048 | AP7: 3.3014641 | AQ7: 27831.892 | AR7: 330 | AS7: 1800 | AT7: 8796 | AU7: 15832800 | AV7: 481861.03 | AW7: 24558.197 | AX7: 28284.443 | AY7: -3726.2462 | AZ7: 2316 | BA7: 6491 | BB7: 6570 | BC7: 2214 | BD7: 2002 | BE7: 6491 | BF7: 829.791 | BG7: 616 | BH7: 616 | BI7: 6570 | BJ7: 2316 | BK7: 1781 | BL7: 829.791 | BM7: 1786598 | BN7: 2324 | BO7: 16254.559 | BP7: 80200 | BQ7: 96454.559 | BR7: 786 | BS7: 1786598 | BT7: 1675068 | BU7: 0.0070474312 | BV7: 2002 | BW7: 616 | BX7: 16254.559 | BY7: 80200 | BZ7: 96454.559 | CA7: 2373.408 | CB7: 12557.29 | CC7: 1930.39 | CD7: 25000 | CE7: 264999 | CF7: 12707977 | CG7: 37.07 | CH7: 700424 | CI7: 134 | CJ7: 1930390 | CK7: 25000 | CL7: 264999 | CM7: 962659 | CN7: -934374.56 | CO7: 1237239 | CP7: 0 | CQ7: 1700 | CR7: 57.64 | CS7: 69.75 | CT7: 518 | CU7: 90.78 | CV7: 2729 | CW7: 25304.62 | CX7: 59.76 | CY7: 57.64 | CZ7: 69.75 | DA7: 518 | DB7: 90.78 | DC7: 2729 | DD7: 25304.62 | DE7: 101.65 | DF7: 662.4 | DG7: 66.86 | DH7: 68.2 | DI7: 99.65 | DJ7: 101.65 | DK7: 662.4 | DL7: 85.599 | DM7: 2467 | DN7: 66.86 | DO7: 68.2 | DP7: 99.65
B8: 2 | C8: 428.7935 | D8: 2366.5 | E8: 1175 | F8: 2.012192 | G8: 90.3545 | H8: 2243 | I8: 40.285 | J8: 399448 | K8: 127.5 | L8: 2.805 | M8: 128 | N8: 17288.463 | O8: 428.7935 | P8: 17288.463 | Q8: 91701.463 | R8: 74413 | S8: 11312.355 | T8: 0.1232 | U8: 91701.463 | V8: 59320.474 | W8: 0.0026 | X8: 22786128 | Y8: 977.785 | Z8: 7238.5 | AA8: 1821.619 | AB8: 795.252 | AC8: 1343.0425 | AD8: 0.054 | AE8: 813.44735 | AF8: 968505 | AG8: 24860.142 | AH8: 22786128 | AI8: 59320.474 | AJ8: 795252 | AK8: 28441.738 | AL8: 5442.95 | AM8: 7238.5 | AN8: 232.69473 | AO8: 45.270229 | AP8: 3.3015725 | AQ8: 28058.167 | AR8: 340 | AS8: 1900 | AT8: 8814 | AU8: 16748400 | AV8: 524523.23 | AW8: 24860.142 | AX8: 28441.738 | AY8: -3581.5961 | AZ8: 2506 | BA8: 6530.5 | BB8: 6603.5 | BC8: 2366.5 | BD8: 2002 | BE8: 6530.5 | BF8: 813.44735 | BG8: 635 | BH8: 635 | BI8: 6603.5 | BJ8: 2506 | BK8: 2011 | BL8: 813.44735 | BM8: 1855002 | BN8: 2484 | BO8: 17288.463 | BP8: 74413 | BQ8: 91701.463 | BR8: 795.252 | BS8: 1855002 | BT8: 1730833 | BU8: 0.0064639822 | BV8: 2002 | BW8: 635 | BX8: 17288.463 | BY8: 74413 | BZ8: 91701.463 | CA8: 2481.47 | CB8: 12731.518 | CC8: 1970.6065 | CD8: 26500 | CE8: 266068 | CF8: 12806861 | CG8: 39.575 | CH8: 741074 | CI8: 135.5 | CJ8: 1970606.5 | CK8: 26500 | CL8: 266068 | CM8: 968505 | CN8: -940063.26 | CO8: 1271861 | CP8: 0 | CQ8: 1750 | CR8: 58.695 | CS8: 69.695 | CT8: 511 | CU8: 90.715 | CV8: 2774 | CW8: 25790.745 | CX8: 58.7 | CY8: 58.695 | CZ8: 69.695 | DA8: 511 | DB8: 90.715 | DC8: 2774 | DD8: 25790.745 | DE8: 101.095 | DF8: 685.05 | DG8: 66.99 | DH8: 68.36 | DI8: 100.65 | DJ8: 101.095 | DK8: 685.05 | DL8: 90.3545 | DM8: 2243 | DN8: 66.99 | DO8: 68.36 | DP8: 100.65
A9: 2003 | B9: 1 | C9: 438.439 | D9: 2519 | E9: 1200 | F9: 2.0991667 | G9: 95.11 | H9: 2019 | I9: 41.79 | J9: 419148 | K9: 126 | L9: 2.74 | M9: 129 | N9: 18322.366 | O9: 438.439 | P9: 18322.366 | Q9: 86948.366 | R9: 68626 | S9: 10442.499 | T9: 0.1201 | U9: 86948.366 | V9: 63589.193 | W9: 0.0027 | X9: 23551553 | Y9: 981.219 | Z9: 7291 | AA9: 1887.688 | AB9: 804.504 | AC9: 1379.602 | AD9: 0.055 | AE9: 797.1037 | AF9: 974351 | AG9: 25162.087 | AH9: 23551553 | AI9: 63589.193 | AJ9: 804504 | AK9: 28599.033 | AL9: 5793.7 | AM9: 7291 | AN9: 233.40662 | AO9: 45.566411 | AP9: 3.3016809 | AQ9: 28284.443 | AR9: 350 | AS9: 2000 | AT9: 8832 | AU9: 17664000 | AV9: 567185.44 | AW9: 25162.087 | AX9: 28599.033 | AY9: -3436.9461 | AZ9: 2696 | BA9: 6570 | BB9: 6637 | BC9: 2519 | BD9: 2003 | BE9: 6570 | BF9: 797.1037 | BG9: 654 | BH9: 654 | BI9: 6637 | BJ9: 2696 | BK9: 2241 | BL9: 797.1037 | BM9: 1923406 | BN9: 2644 | BO9: 18322.366 | BP9: 68626 | BQ9: 86948.366 | BR9: 804.504 | BS9: 1923406 | BT9: 1786598 | BU9: 0.0058805333 | BV9: 2003 | BW9: 654 | BX9: 18322.366 | BY9: 68626 | BZ9: 86948.366 | CA9: 2589.532 | CB9: 12905.745 | CC9: 2010.823 | CD9: 28000 | CE9: 267137 | CF9: 12905745 | CG9: 42.08 | CH9: 781724 | CI9: 137 | CJ9: 2010823 | CK9: 28000 | CL9: 267137 | CM9: 974351 | CN9: -945751.97 | CO9: 1306483 | CP9: 0 | CQ9: 1800 | CR9: 59.75 | CS9: 69.64 | CT9: 504 | CU9: 90.65 | CV9: 2819 | CW9: 26276.87 | CX9: 57.64 | CY9: 59.75 | CZ9: 69.64 | DA9: 504 | DB9: 90.65 | DC9: 2819 | DD9: 26276.87 | DE9: 100.54 | DF9: 707.7 | DG9: 67.12 | DH9: 68.52 | DI9: 101.65 | DJ9: 100.54 | DK9: 707.7 | DL9: 95.11 | DM9: 2019 | DN9: 67.12 | DO9: 68.52 | DP9: 101.65
B10: 2 | C10: 455.9575 | D10: 2630 | E10: 1225 | F10: 2.1459833 | G10: 101.5945 | H10: 1941.5 | I10: 44.64 | J10: 428793.5 | K10: 123 | L10: 2.805 | M10: 127.5 | N10: 20403.871 | O10: 455.9575 | P10: 20403.871 | Q10: 108111.87 | R10: 87708 | S10: 13132.902 | T10: 0.12125 | U10: 108111.87 | V10: 66722.747 | W10: 0.00275 | X10: 24250116 | Y10: 986.175 | Z10: 7294 | AA10: 1981.035 | AB10: 844.287 | AC10: 1418.2075 | AD10: 0.054 | AE10: 807.55145 | AF10: 977785 | AG10: 25314.893 | AH10: 24250116 | AI10: 66722.747 | AJ10: 844287 | AK10: 28802.069 | AL10: 6049 | AM10: 7294 | AN10: 234.12288 | AO10: 45.866494 | AP10: 3.3017893 | AQ10: 28441.738 | AR10: 340.5 | AS10: 2150 | AT10: 8849.5 | AU10: 19029050 | AV10: 445995.49 | AW10: 25314.893 | AX10: 28802.069 | AY10: -3487.1754 | AZ10: 2974 | BA10: 6603.5 | BB10: 6660 | BC10: 2630 | BD10: 2003 | BE10: 6603.5 | BF10: 807.55145 | BG10: 634 | BH10: 634 | BI10: 6660 | BJ10: 2974 | BK10: 2235 | BL10: 807.55145 | BM10: 1951855.5 | BN10: 2761 | BO10: 20403.871 | BP10: 87708 | BQ10: 108111.87 | BR10: 844.287 | BS10: 1951855.5 | BT10: 1855002 | BU10: 0.010709032 | BV10: 2003 | BW10: 634 | BX10: 20403.871 | BY10: 87708 | BZ10: 108111.87 | CA10: 2722.827 | CB10: 13084.807 | CC10: 2048.3695 | CD10: 28500 | CE10: 267404.5 | CF10: 13880639 | CG10: 44.93 | CH10: 822277 | CI10: 130.5 | CJ10: 2048369.5 | CK10: 28500 | CL10: 267404.5 | CM10: 977785 | CN10: -948982.93 | CO10: 1343042.5 | CP10: 0 | CQ10: 1900 | CR10: 59.25 | CS10: 69.81 | CT10: 515.5 | CU10: 90.67 | CV10: 2858 | CW10: 26572.415 | CX10: 58.695 | CY10: 59.25 | CZ10: 69.81 | DA10: 515.5 | DB10: 90.67 | DC10: 2858 | DD10: 26572.415 | DE10: 99.55 | DF10: 731.895 | DG10: 66.995 | DH10: 68.68 | DI10: 101.095 | DJ10: 99.55 | DK10: 731.895 | DL10: 101.5945 | DM10: 1941.5 | DN10: 66.995 | DO10: 68.68 | DP10: 101.095
A11: 2004 | B11: 1 | C11: 473.476 | D11: 2741 | E11: 1250 | F11: 2.1928 | G11: 108.079 | H11: 1864 | I11: 47.49 | J11: 438439 | K11: 120 | L11: 2.87 | M11: 126 | N11: 22485.375 | O11: 473.476 | P11: 22485.375 | Q11: 129275.38 | R11: 106790 | S11: 15823.306 | T11: 0.1224 | U11: 129275.38 | V11: 69856.301 | W11: 0.0028 | X11: 24948679 | Y11: 991.131 | Z11: 7297 | AA11: 2074.382 | AB11: 884.07 | AC11: 1456.813 | AD11: 0.053 | AE11: 817.9992 | AF11: 981219 | AG11: 25467.699 | AH11: 24948679 | AI11: 69856.301 | AJ11: 884070 | AK11: 29005.104 | AL11: 6304.3 | AM11: 7297 | AN11: 234.83913 | AO11: 46.166576 | AP11: 3.3018977 | AQ11: 28599.033 | AR11: 331 | AS11: 2300 | AT11: 8867 | AU11: 20394100 | AV11: 324805.54 | AW11: 25467.699 | AX11: 29005.104 | AY11: -3537.4047 | AZ11: 3252 | BA11: 6637 | BB11: 6683 | BC11: 2741 | BD11: 2004 | BE11: 6637 | BF11: 817.9992 | BG11: 614 | BH11: 614 | BI11: 6683 | BJ11: 3252 | BK11: 2229 | BL11: 817.9992 | BM11: 1980305 | BN11: 2878 | BO11: 22485.375 | BP11: 106790 | BQ11: 129275.38 | BR11: 884.07 | BS11: 1980305 | BT11: 1923406 | BU11: 0.015537531 | BV11: 2004 | BW11: 614 | BX11: 22485.375 | BY11: 106790 | BZ11: 129275.38 | CA11: 2856.122 | CB11: 13263.869 | CC11: 2085.916 | CD11: 29000 | CE11: 267672 | CF11: 14855533 | CG11: 47.78 | CH11: 862830 | CI11: 124 | CJ11: 2085916 | CK11: 29000 | CL11: 267672 | CM11: 981219 | CN11: -952213.9 | CO11: 1379602 | CP11: 0 | CQ11: 2000 | CR11: 58.75 | CS11: 69.98 | CT11: 527 | CU11: 90.69 | CV11: 2897 | CW11: 26867.96 | CX11: 59.75 | CY11: 58.75 | CZ11: 69.98 | DA11: 527 | DB11: 90.69 | DC11: 2897 | DD11: 26867.96 | DE11: 98.56 | DF11: 756.09 | DG11: 66.87 | DH11: 68.84 | DI11: 100.54 | DJ11: 98.56 | DK11: 756.09 | DL11: 108.079 | DM11: 1864 | DN11: 66.87 | DO11: 68.84 | DP11: 100.54
B12: 2 | C12: 486.99 | D12: 2770.5 | E12: 1275 | F12: 2.1733231 | G12: 112.7785 | H12: 2124 | I12: 48.535 | J12: 455957.5 | K12: 123.5 | L12: 2.905 | M12: 123 | N12: 23650.182 | O12: 486.99 | P12: 23650.182 | Q12: 122070.18 | R12: 98420 | S12: 14332.606 | T12: 0.1171 | U12: 122070.18 | V12: 73331.106 | W12: 0.00285 | X12: 25716738 | Y12: 995.1275 | Z12: 7301.5 | AA12: 2229.3645 | AB12: 890.8015 | AC12: 1497.579 | AD12: 0.055 | AE12: 787.5544 | AF12: 986175 | AG12: 25648.504 | AH12: 25716738 | AI12: 73331.106 | AJ12: 890801.5 | AK12: 29151.594 | AL12: 6372.15 | AM12: 7301.5 | AN12: 235.55979 | AO12: 46.470612 | AP12: 3.302006 | AQ12: 28802.069 | AR12: 311.5 | AS12: 2400 | AT12: 8884.5 | AU12: 21324550 | AV12: 861561.82 | AW12: 25648.504 | AX12: 29151.594 | AY12: -3503.09 | AZ12: 3191 | BA12: 6660 | BB12: 6727.5 | BC12: 2770.5 | BD12: 2004 | BE12: 6660 | BF12: 787.5544 | BG12: 574 | BH12: 574 | BI12: 6727.5 | BJ12: 3191 | BK12: 2354.5 | BL12: 787.5544 | BM12: 1991053 | BN12: 2909 | BO12: 23650.182 | BP12: 98420 | BQ12: 122070.18 | BR12: 890.8015 | BS12: 1991053 | BT12: 1951855.5 | BU12: 0.02864551 | BV12: 2004 | BW12: 574 | BX12: 23650.182 | BY12: 98420 | BZ12: 122070.18 | CA12: 2872.861 | CB12: 13426.95 | CC12: 2124.8645 | CD12: 30750 | CE12: 268887.5 | CF12: 13353020 | CG12: 49.325 | CH12: 878014.5 | CI12: 130.5 | CJ12: 2124864.5 | CK12: 30750 | CL12: 268887.5 | CM12: 986175 | CN12: -957023.41 | CO12: 1418207.5 | CP12: 0 | CQ12: 2150 | CR12: 59.49 | CS12: 69.81 | CT12: 537.5 | CU12: 90.85 | CV12: 2960.5 | CW12: 27198.305 | CX12: 59.25 | CY12: 59.49 | CZ12: 69.81 | DA12: 537.5 | DB12: 90.85 | DC12: 2960.5 | DD12: 27198.305 | DE12: 98.14 | DF12: 781.94 | DG12: 67 | DH12: 69 | DI12: 99.55 | DJ12: 98.14 | DK12: 781.94 | DL12: 112.7785 | DM12: 2124 | DN12: 67 | DO12: 69 | DP12: 99.55
A13: 2005 | B13: 1 | C13: 500.504 | D13: 2800 | E13: 1300 | F13: 2.1538462 | G13: 117.478 | H13: 2384 | I13: 49.58 | J13: 473476 | K13: 127 | L13: 2.94 | M13: 120 | N13: 24814.988 | O13: 500.504 | P13: 24814.988 | Q13: 114864.99 | R13: 90050 | S13: 12841.906 | T13: 0.1118 | U13: 114864.99 | V13: 76805.911 | W13: 0.0029 | X13: 26484797 | Y13: 999.124 | Z13: 7306 | AA13: 2384.347 | AB13: 897.533 | AC13: 1538.345 | AD13: 0.057 | AE13: 757.1096 | AF13: 991131 | AG13: 25829.31 | AH13: 26484797 | AI13: 76805.911 | AJ13: 897533 | AK13: 29298.085 | AL13: 6440 | AM13: 7306 | AN13: 236.28045 | AO13: 46.774647 | AP13: 3.3021144 | AQ13: 29005.104 | AR13: 292 | AS13: 2500 | AT13: 8902 | AU13: 22255000 | AV13: 1398318.1 | AW13: 25829.31 | AX13: 29298.085 | AY13: -3468.7754 | AZ13: 3130 | BA13: 6683 | BB13: 6772 | BC13: 2800 | BD13: 2005 | BE13: 6683 | BF13: 757.1096 | BG13: 534 | BH13: 534 | BI13: 6772 | BJ13: 3130 | BK13: 2480 | BL13: 757.1096 | BM13: 2001801 | BN13: 2940 | BO13: 24814.988 | BP13: 90050 | BQ13: 114864.99 | BR13: 897.533 | BS13: 2001801 | BT13: 1980305 | BU13: 0.041753489 | BV13: 2005 | BW13: 534 | BX13: 24814.988 | BY13: 90050 | BZ13: 114864.99 | CA13: 2889.6 | CB13: 13590.03 | CC13: 2163.813 | CD13: 32500 | CE13: 270103 | CF13: 11850506 | CG13: 50.87 | CH13: 893199 | CI13: 137 | CJ13: 2163813 | CK13: 32500 | CL13: 270103 | CM13: 991131 | CN13: -961832.92 | CO13: 1456813 | CP13: 0 | CQ13: 2300 | CR13: 60.23 | CS13: 69.64 | CT13: 548 | CU13: 91.01 | CV13: 3024 | CW13: 27528.65 | CX13: 58.75 | CY13: 60.23 | CZ13: 69.64 | DA13: 548 | DB13: 91.01 | DC13: 3024 | DD13: 27528.65 | DE13: 97.72 | DF13: 807.79 | DG13: 67.13 | DH13: 69.16 | DI13: 98.56 | DJ13: 97.72 | DK13: 807.79 | DL13: 117.478 | DM13: 2384 | DN13: 67.13 | DO13: 69.16 | DP13: 98.56
B14: 2 | C14: 511.4755 | D14: 2830 | E14: 1325 | F14: 2.1361823 | G14: 127.844 | H14: 2232 | I14: 49.265 | J14: 486990 | K14: 126.5 | L14: 3.005 | M14: 123.5 | N14: 25194.384 | O14: 511.4755 | P14: 25194.384 | Q14: 121972.38 | R14: 96778 | S14: 13597.789 | T14: 0.1115 | U14: 121972.38 | V14: 80531.477 | W14: 0.00295 | X14: 27285239 | Y14: 1001.634 | Z14: 7360.5 | AA14: 2408.6775 | AB14: 911.4125 | AC14: 1581.3925 | AD14: 0.0565 | AE14: 760.6936 | AF14: 995127.5 | AG14: 25956.651 | AH14: 27285239 | AI14: 80531.477 | AJ14: 911412.5 | AK14: 29536.281 | AL14: 6509 | AM14: 7360.5 | AN14: 237.00552 | AO14: 47.082686 | AP14: 3.3022227 | AQ14: 29151.594 | AR14: 294.5 | AS14: 2700 | AT14: 8919 | AU14: 24084700 | AV14: 802072.87 | AW14: 25956.651 | AX14: 29536.281 | AY14: -3579.6295 | AZ14: 3209.5 | BA14: 6727.5 | BB14: 6822.5 | BC14: 2830 | BD14: 2005 | BE14: 6727.5 | BF14: 760.6936 | BG14: 538 | BH14: 538 | BI14: 6822.5 | BJ14: 3209.5 | BK14: 2405.5 | BL14: 760.6936 | BM14: 2091648.5 | BN14: 2971.5 | BO14: 25194.384 | BP14: 96778 | BQ14: 121972.38 | BR14: 911.4125 | BS14: 2091648.5 | BT14: 1991053 | BU14: 0.023451363 | BV14: 2005 | BW14: 538 | BX14: 25194.384 | BY14: 96778 | BZ14: 121972.38 | CA14: 2916.27 | CB14: 13792.971 | CC14: 2207.7195 | CD14: 33000 | CE14: 272020.5 | CF14: 12167430 | CG14: 50.555 | CH14: 954099 | CI14: 133 | CJ14: 2207719.5 | CK14: 33000 | CL14: 272020.5 | CM14: 995127.5 | CN14: -965591.22 | CO14: 1497579 | CP14: 0 | CQ14: 2400 | CR14: 61.49 | CS14: 69.82 | CT14: 528.5 | CU14: 91.22 | CV14: 3085.5 | CW14: 28072.355 | CX14: 59.49 | CY14: 61.49 | CZ14: 69.82 | DA14: 528.5 | DB14: 91.22 | DC14: 3085.5 | DD14: 28072.355 | DE14: 100.35 | DF14: 783.495 | DG14: 67.005 | DH14: 69.32 | DI14: 98.14 | DJ14: 100.35 | DK14: 783.495 | DL14: 127.844 | DM14: 2232 | DN14: 67.005 | DO14: 69.32 | DP14: 98.14
A15: 2006 | B15: 1 | C15: 522.447 | D15: 2860 | E15: 1350 | F15: 2.1185185 | G15: 138.21 | H15: 2080 | I15: 48.95 | J15: 500504 | K15: 126 | L15: 3.07 | M15: 127 | N15: 25573.781 | O15: 522.447 | P15: 25573.781 | Q15: 129079.78 | R15: 103506 | S15: 14353.672 | T15: 0.1112 | U15: 129079.78 | V15: 84257.043 | W15: 0.003 | X15: 28085681 | Y15: 1004.144 | Z15: 7415 | AA15: 2433.008 | AB15: 925.292 | AC15: 1624.44 | AD15: 0.056 | AE15: 764.2776 | AF15: 999124 | AG15: 26083.993 | AH15: 28085681 | AI15: 84257.043 | AJ15: 925292 | AK15: 29774.477 | AL15: 6578 | AM15: 7415 | AN15: 237.7306 | AO15: 47.390726 | AP15: 3.3023309 | AQ15: 29298.085 | AR15: 297 | AS15: 2900 | AT15: 8936 | AU15: 25914400 | AV15: 205827.64 | AW15: 26083.993 | AX15: 29774.477 | AY15: -3690.4837 | AZ15: 3289 | BA15: 6772 | BB15: 6873 | BC15: 2860 | BD15: 2006 | BE15: 6772 | BF15: 764.2776 | BG15: 542 | BH15: 542 | BI15: 6873 | BJ15: 3289 | BK15: 2331 | BL15: 764.2776 | BM15: 2181496 | BN15: 3003 | BO15: 25573.781 | BP15: 103506 | BQ15: 129079.78 | BR15: 925.292 | BS15: 2181496 | BT15: 2001801 | BU15: 0.0051492362 | BV15: 2006 | BW15: 542 | BX15: 25573.781 | BY15: 103506 | BZ15: 129079.78 | CA15: 2942.94 | CB15: 13995.912 | CC15: 2251.626 | CD15: 33500 | CE15: 273938 | CF15: 12484353 | CG15: 50.24 | CH15: 1014999 | CI15: 129 | CJ15: 2251626 | CK15: 33500 | CL15: 273938 | CM15: 999124 | CN15: -969349.52 | CO15: 1538345 | CP15: 0 | CQ15: 2500 | CR15: 62.75 | CS15: 70 | CT15: 509 | CU15: 91.43 | CV15: 3147 | CW15: 28616.06 | CX15: 60.23 | CY15: 62.75 | CZ15: 70 | DA15: 509 | DB15: 91.43 | DC15: 3147 | DD15: 28616.06 | DE15: 102.98 | DF15: 759.2 | DG15: 66.88 | DH15: 69.48 | DI15: 97.72 | DJ15: 102.98 | DK15: 759.2 | DL15: 138.21 | DM15: 2080 | DN15: 66.88 | DO15: 69.48 | DP15: 97.72
B16: 2 | C16: 546.714 | D16: 2993 | E16: 1375 | F16: 2.1756878 | G16: 156.5795 | H16: 1947.5 | I16: 49.235 | J16: 511475.5 | K16: 123 | L16: 3.16 | M16: 126.5 | N16: 26924.38 | O16: 546.714 | P16: 26924.38 | Q16: 140287.88 | R16: 113363.5 | S16: 15751.508 | T16: 0.1122 | U16: 140287.88 | V16: 86803.518 | W16: 0.003 | X16: 28934506 | Y16: 1007.6835 | Z16: 7471 | AA16: 2457.8345 | AB16: 940.586 | AC16: 1669.897 | AD16: 0.055 | AE16: 779.8104 | AF16: 1001634 | AG16: 26668.722 | AH16: 28934506 | AI16: 86803.518 | AJ16: 940586 | AK16: 30016.546 | AL16: 6883.9 | AM16: 7471 | AN16: 238.46013 | AO16: 47.702823 | AP16: 3.3024392 | AQ16: 29536.281 | AR16: 287.25 | AS16: 2950 | AT16: 8945.5 | AU16: 26389700 | AV16: 842022.13 | AW16: 26668.722 | AX16: 30016.546 | AY16: -3347.8245 | AZ16: 3441.5 | BA16: 6822.5 | BB16: 6949.5 | BC16: 2993 | BD16: 2006 | BE16: 6822.5 | BF16: 779.8104 | BG16: 521.5 | BH16: 521.5 | BI16: 6949.5 | BJ16: 3441.5 | BK16: 2344 | BL16: 779.8104 | BM16: 2223487.5 | BN16: 3142.5 | BO16: 26924.38 | BP16: 113363.5 | BQ16: 140287.88 | BR16: 940.586 | BS16: 2223487.5 | BT16: 2091648.5 | BU16: 0.0082655317 | BV16: 2006 | BW16: 521.5 | BX16: 26924.38 | BY16: 113363.5 | BZ16: 140287.88 | CA16: 3076.671 | CB16: 14167.993 | CC16: 2302.2115 | CD16: 34250 | CE16: 276306.5 | CF16: 14200917 | CG16: 54.525 | CH16: 1028546.5 | CI16: 128.5 | CJ16: 2302211.5 | CK16: 34250 | CL16: 276306.5 | CM16: 1001634 | CN16: -971617.45 | CO16: 1581392.5 | CP16: 0 | CQ16: 2700 | CR16: 62.2 | CS16: 70.115 | CT16: 502 | CU16: 91.54 | CV16: 3196 | CW16: 29119.655 | CX16: 61.49 | CY16: 62.2 | CZ16: 70.115 | DA16: 502 | DB16: 91.54 | DC16: 3196 | DD16: 29119.655 | DE16: 100.815 | DF16: 780.865 | DG16: 67.01 | DH16: 69.64 | DI16: 100.35 | DJ16: 100.815 | DK16: 780.865 | DL16: 156.5795 | DM16: 1947.5 | DN16: 67.01 | DO16: 69.64 | DP16: 100.35
A17: 2007 | B17: 1 | C17: 570.981 | D17: 3126 | E17: 1400 | F17: 2.2328571 | G17: 174.949 | H17: 1815 | I17: 49.52 | J17: 522447 | K17: 120 | L17: 3.25 | M17: 126 | N17: 28274.979 | O17: 570.981 | P17: 28274.979 | Q17: 151495.98 | R17: 123221 | S17: 17149.345 | T17: 0.1132 | U17: 151495.98 | V17: 89349.993 | W17: 0.003 | X17: 29783331 | Y17: 1011.223 | Z17: 7527 | AA17: 2482.661 | AB17: 955.88 | AC17: 1715.354 | AD17: 0.054 | AE17: 795.3432 | AF17: 1004144 | AG17: 27253.45 | AH17: 29783331 | AI17: 89349.993 | AJ17: 955880 | AK17: 30258.615 | AL17: 7189.8 | AM17: 7527 | AN17: 239.18966 | AO17: 48.01492 | AP17: 3.3025474 | AQ17: 29774.477 | AR17: 277.5 | AS17: 3000 | AT17: 8955 | AU17: 26865000 | AV17: 1478216.6 | AW17: 27253.45 | AX17: 30258.615 | AY17: -3005.1653 | AZ17: 3594 | BA17: 6873 | BB17: 7026 | BC17: 3126 | BD17: 2007 | BE17: 6873 | BF17: 795.3432 | BG17: 501 | BH17: 501 | BI17: 7026 | BJ17: 3594 | BK17: 2357 | BL17: 795.3432 | BM17: 2265479 | BN17: 3282 | BO17: 28274.979 | BP17: 123221 | BQ17: 151495.98 | BR17: 955.88 | BS17: 2265479 | BT17: 2181496 | BU17: 0.011381827 | BV17: 2007 | BW17: 501 | BX17: 28274.979 | BY17: 123221 | BZ17: 151495.98 | CA17: 3210.402 | CB17: 14340.073 | CC17: 2352.797 | CD17: 35000 | CE17: 278675 | CF17: 15917481 | CG17: 58.81 | CH17: 1042094 | CI17: 128 | CJ17: 2352797 | CK17: 35000 | CL17: 278675 | CM17: 1004144 | CN17: -973885.39 | CO17: 1624440 | CP17: 0 | CQ17: 2900 | CR17: 61.65 | CS17: 70.23 | CT17: 495 | CU17: 91.65 | CV17: 3245 | CW17: 29623.25 | CX17: 62.75 | CY17: 61.65 | CZ17: 70.23 | DA17: 495 | DB17: 91.65 | DC17: 3245 | DD17: 29623.25 | DE17: 98.65 | DF17: 802.53 | DG17: 67.14 | DH17: 69.8 | DI17: 102.98 | DJ17: 98.65 | DK17: 802.53 | DL17: 174.949 | DM17: 1815 | DN17: 67.14 | DO17: 69.8 | DP17: 102.98
B18: 2 | C18: 593.463 | D18: 3194.5 | E18: 1425 | F18: 2.241601 | G18: 186.8775 | H18: 2134 | I18: 50.14 | J18: 546714 | K18: 123.5 | L18: 3.285 | M18: 123 | N18: 29770.174 | O18: 593.463 | P18: 29770.174 | Q18: 162197.17 | R18: 132427 | S18: 18265.626 | T18: 0.11265 | U18: 162197.17 | V18: 91800.52 | W18: 0.003 | X18: 30600174 | Y18: 1011.729 | Z18: 7533.5 | AA18: 2651.9335 | AB18: 968.6385 | AC18: 1763.355 | AD18: 0.0565 | AE18: 807.8455 | AF18: 1007683.5 | AG18: 28311.903 | AH18: 30600174 | AI18: 91800.52 | AJ18: 968638.5 | AK18: 30442.372 | AL18: 7347.35 | AM18: 7533.5 | AN18: 239.92367 | AO18: 48.331128 | AP18: 3.3026555 | AQ18: 30016.546 | AR18: 208.25 | AS18: 3250 | AT18: 8968 | AU18: 29149250 | AV18: 1986548.5 | AW18: 28311.903 | AX18: 30442.372 | AY18: -2130.4687 | AZ18: 3673 | BA18: 6949.5 | BB18: 7172 | BC18: 3194.5 | BD18: 2007 | BE18: 6949.5 | BF18: 807.8455 | BG18: 361.5 | BH18: 361.5 | BI18: 7172 | BJ18: 3673 | BK18: 2515 | BL18: 807.8455 | BM18: 2319315.5 | BN18: 3354 | BO18: 29770.174 | BP18: 132427 | BQ18: 162197.17 | BR18: 968.6385 | BS18: 2319315.5 | BT18: 2223487.5 | BU18: 0.010248217 | BV18: 2007 | BW18: 361.5 | BX18: 29770.174 | BY18: 132427 | BZ18: 162197.17 | CA18: 3266.068 | CB18: 14486.4 | CC18: 2396.7285 | CD18: 37000 | CE18: 279657.5 | CF18: 15428748 | CG18: 54.93 | CH18: 1077721 | CI18: 129 | CJ18: 2396728.5 | CK18: 37000 | CL18: 279657.5 | CM18: 1007683.5 | CN18: -977241.13 | CO18: 1669897 | CP18: 0 | CQ18: 2950 | CR18: 61.315 | CS18: 70.385 | CT18: 497.5 | CU18: 91.7975 | CV18: 3295 | CW18: 30176.38 | CX18: 62.2 | CY18: 61.315 | CZ18: 70.385 | DA18: 497.5 | DB18: 91.7975 | DC18: 3295 | DD18: 30176.38 | DE18: 100.885 | DF18: 785.62 | DG18: 67.015 | DH18: 69.96 | DI18: 100.815 | DJ18: 100.885 | DK18: 785.62 | DL18: 186.8775 | DM18: 2134 | DN18: 67.015 | DO18: 69.96 | DP18: 100.815
A19: 2008 | B19: 1 | C19: 615.945 | D19: 3263 | E19: 1450 | F19: 2.2503448 | G19: 198.806 | H19: 2453 | I19: 50.76 | J19: 570981 | K19: 127 | L19: 3.32 | M19: 120 | N19: 31265.368 | O19: 615.945 | P19: 31265.368 | Q19: 172898.37 | R19: 141633 | S19: 19381.907 | T19: 0.1121 | U19: 172898.37 | V19: 94251.048 | W19: 0.003 | X19: 31417016 | Y19: 1012.235 | Z19: 7540 | AA19: 2821.206 | AB19: 981.397 | AC19: 1811.356 | AD19: 0.059 | AE19: 820.3478 | AF19: 1011223 | AG19: 29370.356 | AH19: 31417016 | AI19: 94251.048 | AJ19: 981397 | AK19: 30626.128 | AL19: 7504.9 | AM19: 7540 | AN19: 240.65767 | AO19: 48.647336 | AP19: 3.3027637 | AQ19: 30258.615 | AR19: 139 | AS19: 3500 | AT19: 8981 | AU19: 31433500 | AV19: 2494880.4 | AW19: 29370.356 | AX19: 30626.128 | AY19: -1255.7722 | AZ19: 3752 | BA19: 7026 | BB19: 7318 | BC19: 3263 | BD19: 2008 | BE19: 7026 | BF19: 820.3478 | BG19: 222 | BH19: 222 | BI19: 7318 | BJ19: 3752 | BK19: 2673 | BL19: 820.3478 | BM19: 2373152 | BN19: 3426 | BO19: 31265.368 | BP19: 141633 | BQ19: 172898.37 | BR19: 981.397 | BS19: 2373152 | BT19: 2265479 | BU19: 0.0091146063 | BV19: 2008 | BW19: 222 | BX19: 31265.368 | BY19: 141633 | BZ19: 172898.37 | CA19: 3321.734 | CB19: 14632.728 | CC19: 2440.66 | CD19: 39000 | CE19: 280640 | CF19: 14940015 | CG19: 51.05 | CH19: 1113348 | CI19: 130 | CJ19: 2440660 | CK19: 39000 | CL19: 280640 | CM19: 1011223 | CN19: -980596.87 | CO19: 1715354 | CP19: 0 | CQ19: 3000 | CR19: 60.98 | CS19: 70.54 | CT19: 500 | CU19: 91.945 | CV19: 3345 | CW19: 30729.51 | CX19: 61.65 | CY19: 60.98 | CZ19: 70.54 | DA19: 500 | DB19: 91.945 | DC19: 3345 | DD19: 30729.51 | DE19: 103.12 | DF19: 768.71 | DG19: 66.89 | DH19: 70.12 | DI19: 98.65 | DJ19: 103.12 | DK19: 768.71 | DL19: 198.806 | DM19: 2453 | DN19: 66.89 | DO19: 70.12 | DP19: 98.65
B20: 2 | C20: 638.061 | D20: 3380.5 | E20: 1475 | F20: 2.2911724 | G20: 206.288 | H20: 2383.5 | I20: 51.47 | J20: 593463 | K20: 129.5 | L20: 3.57 | M20: 123.5 | N20: 32856.702 | O20: 638.061 | P20: 32856.702 | Q20: 176680.2 | R20: 143823.5 | S20: 19841.943 | T20: 0.1123 | U20: 176680.2 | V20: 98547.25 | W20: 0.00305 | X20: 32296162 | Y20: 1013.2495 | Z20: 7597.5 | AA20: 2943.867 | AB20: 1006.138 | AC20: 1862.0435 | AD20: 0.058 | AE20: 823.66765 | AF20: 1011729 | AG20: 29638.867 | AH20: 32296162 | AI20: 98547.25 | AJ20: 1006138 | AK20: 30890.952 | AL20: 7775.15 | AM20: 7597.5 | AN20: 241.39618 | AO20: 48.967708 | AP20: 3.3028718 | AQ20: 30442.372 | AR20: 160 | AS20: 3650 | AT20: 8995.5 | AU20: 32835750 | AV20: 1559300.2 | AW20: 29638.867 | AX20: 30890.952 | AY20: -1252.0847 | AZ20: 3887 | BA20: 7172 | BB20: 7334.5 | BC20: 3380.5 | BD20: 2008 | BE20: 7172 | BF20: 823.66765 | BG20: 263 | BH20: 263 | BI20: 7334.5 | BJ20: 3887 | BK20: 2773 | BL20: 823.66765 | BM20: 2527491.5 | BN20: 3549 | BO20: 32856.702 | BP20: 143823.5 | BQ20: 176680.2 | BR20: 1006.138 | BS20: 2527491.5 | BT20: 2319315.5 | BU20: 0.0062271268 | BV20: 2008 | BW20: 263 | BX20: 32856.702 | BY20: 143823.5 | BZ20: 176680.2 | CA20: 3460.588 | CB20: 14851.239 | CC20: 2490.1845 | CD20: 39500 | CE20: 282057.5 | CF20: 15245999 | CG20: 51.76 | CH20: 1130564.5 | CI20: 134 | CJ20: 2490184.5 | CK20: 39500 | CL20: 282057.5 | CM20: 1011729 | CN20: -980838.05 | CO20: 1763355 | CP20: 0 | CQ20: 3250 | CR20: 61.915 | CS20: 70.66 | CT20: 478.5 | CU20: 91.9075 | CV20: 3396.5 | CW20: 31253.85 | CX20: 61.315 | CY20: 61.915 | CZ20: 70.66 | DA20: 478.5 | DB20: 91.9075 | DC20: 3396.5 | DD20: 31253.85 | DE20: 101.587 | DF20: 745.59 | DG20: 67.02 | DH20: 70.28 | DI20: 100.885 | DJ20: 101.587 | DK20: 745.59 | DL20: 206.288 | DM20: 2383.5 | DN20: 67.02 | DO20: 70.28 | DP20: 100.885
A21: 2009 | B21: 1 | C21: 660.177 | D21: 3498 | E21: 1500 | F21: 2.332 | G21: 213.77 | H21: 2314 | I21: 52.18 | J21: 615945 | K21: 132 | L21: 3.82 | M21: 127 | N21: 34448.036 | O21: 660.177 | P21: 34448.036 | Q21: 180462.04 | R21: 146014 | S21: 20301.979 | T21: 0.1125 | U21: 180462.04 | V21: 102843.45 | W21: 0.0031 | X21: 33175307 | Y21: 1014.264 | Z21: 7655 | AA21: 3066.528 | AB21: 1030.879 | AC21: 1912.731 | AD21: 0.057 | AE21: 826.9875 | AF21: 1012235 | AG21: 29907.379 | AH21: 33175307 | AI21: 102843.45 | AJ21: 1030879 | AK21: 31155.776 | AL21: 8045.4 | AM21: 7655 | AN21: 242.13469 | AO21: 49.288081 | AP21: 3.3029799 | AQ21: 30626.128 | AR21: 181 | AS21: 3800 | AT21: 9010 | AU21: 34238000 | AV21: 623720.1 | AW21: 29907.379 | AX21: 31155.776 | AY21: -1248.3972 | AZ21: 4022 | BA21: 7318 | BB21: 7351 | BC21: 3498 | BD21: 2009 | BE21: 7318 | BF21: 826.9875 | BG21: 304 | BH21: 304 | BI21: 7351 | BJ21: 4022 | BK21: 2873 | BL21: 826.9875 | BM21: 2681831 | BN21: 3672 | BO21: 34448.036 | BP21: 146014 | BQ21: 180462.04 | BR21: 1030.879 | BS21: 2681831 | BT21: 2373152 | BU21: 0.0033396473 | BV21: 2009 | BW21: 304 | BX21: 34448.036 | BY21: 146014 | BZ21: 180462.04 | CA21: 3599.442 | CB21: 15069.751 | CC21: 2539.709 | CD21: 40000 | CE21: 283475 | CF21: 15551983 | CG21: 52.47 | CH21: 1147781 | CI21: 138 | CJ21: 2539709 | CK21: 40000 | CL21: 283475 | CM21: 1012235 | CN21: -981079.22 | CO21: 1811356 | CP21: 0 | CQ21: 3500 | CR21: 62.85 | CS21: 70.78 | CT21: 457 | CU21: 91.87 | CV21: 3448 | CW21: 31778.19 | CX21: 60.98 | CY21: 62.85 | CZ21: 70.78 | DA21: 457 | DB21: 91.87 | DC21: 3448 | DD21: 31778.19 | DE21: 100.054 | DF21: 722.47 | DG21: 67.15 | DH21: 70.44 | DI21: 103.12 | DJ21: 100.054 | DK21: 722.47 | DL21: 213.77 | DM21: 2314 | DN21: 67.15 | DO21: 70.44 | DP21: 103.12
B22: 2 | C22: 674.289 | D22: 3572.5 | E22: 1575 | F22: 2.2711515 | G22: 237.2325 | H22: 2141 | I22: 50.065 | J22: 638061 | K22: 126 | L22: 3.915 | M22: 129.5 | N22: 33728.432 | O22: 674.289 | P22: 33728.432 | Q22: 186962.93 | R22: 153234.5 | S22: 21033.33 | T22: 0.1125 | U22: 186962.93 | V22: 104708.49 | W22: 0.0031 | X22: 33776932 | Y22: 1017.839 | Z22: 7913 | AA22: 3181.935 | AB22: 1046.8205 | AC22: 1966.255 | AD22: 0.054 | AE22: 829.2375 | AF22: 1013249.5 | AG22: 31352.045 | AH22: 33776932 | AI22: 104708.49 | AJ22: 1046820.5 | AK22: 31329.039 | AL22: 8216.75 | AM22: 7913 | AN22: 242.87774 | AO22: 49.612673 | AP22: 3.303088 | AQ22: 30890.952 | AR22: 300.5 | AS22: 3900 | AT22: 9023.5 | AU22: 35193000 | AV22: 1854025.1 | AW22: 31352.045 | AX22: 31329.039 | AY22: 23.00575 | AZ22: 4108 | BA22: 7334.5 | BB22: 7371 | BC22: 3572.5 | BD22: 2009 | BE22: 7334.5 | BF22: 829.2375 | BG22: 542 | BH22: 542 | BI22: 7371 | BJ22: 4108 | BK22: 2986 | BL22: 829.2375 | BM22: 2814449 | BN22: 3750.5 | BO22: 33728.432 | BP22: 153234.5 | BQ22: 186962.93 | BR22: 1046.8205 | BS22: 2814449 | BT22: 2527491.5 | BU22: 0.0036732508 | BV22: 2009 | BW22: 542 | BX22: 33728.432 | BY22: 153234.5 | BZ22: 186962.93 | CA22: 3685.22 | CB22: 15255.034 | CC22: 2592.6195 | CD22: 41500 | CE22: 284474 | CF22: 15334027 | CG22: 49.355 | CH22: 1167980.5 | CI22: 129.5 | CJ22: 2592619.5 | CK22: 41500 | CL22: 284474 | CM22: 1013249.5 | CN22: -981920.46 | CO22: 1862043.5 | CP22: 0 | CQ22: 3650 | CR22: 60.815 | CS22: 71.105 | CT22: 447.5 | CU22: 91.965 | CV22: 3487 | CW22: 32269.61 | CX22: 61.915 | CY22: 60.815 | CZ22: 71.105 | DA22: 447.5 | DB22: 91.965 | DC22: 3487 | DD22: 32269.61 | DE22: 99.847 | DF22: 751.34 | DG22: 67.025 | DH22: 70.6 | DI22: 101.587 | DJ22: 99.847 | DK22: 751.34 | DL22: 237.2325 | DM22: 2141 | DN22: 67.025 | DO22: 70.6 | DP22: 101.587
A23: 2010 | B23: 1 | C23: 688.401 | D23: 3647 | E23: 1650 | F23: 2.210303 | G23: 260.695 | H23: 1968 | I23: 47.95 | J23: 660177 | K23: 120 | L23: 4.01 | M23: 132 | N23: 33008.828 | O23: 688.401 | P23: 33008.828 | Q23: 193463.83 | R23: 160455 | S23: 21764.681 | T23: 0.1125 | U23: 193463.83 | V23: 106573.53 | W23: 0.0031 | X23: 34378557 | Y23: 1021.414 | Z23: 8171 | AA23: 3297.342 | AB23: 1062.762 | AC23: 2019.779 | AD23: 0.051 | AE23: 831.4875 | AF23: 1014264 | AG23: 32796.711 | AH23: 34378557 | AI23: 106573.53 | AJ23: 1062762 | AK23: 31502.302 | AL23: 8388.1 | AM23: 8171 | AN23: 243.62078 | AO23: 49.937265 | AP23: 3.3031961 | AQ23: 31155.776 | AR23: 420 | AS23: 4000 | AT23: 9037 | AU23: 36148000 | AV23: 3084330.2 | AW23: 32796.711 | AX23: 31502.302 | AY23: 1294.4087 | AZ23: 4194 | BA23: 7351 | BB23: 7391 | BC23: 3647 | BD23: 2010 | BE23: 7351 | BF23: 831.4875 | BG23: 780 | BH23: 780 | BI23: 7391 | BJ23: 4194 | BK23: 3099 | BL23: 831.4875 | BM23: 2947067 | BN23: 3829 | BO23: 33008.828 | BP23: 160455 | BQ23: 193463.83 | BR23: 1062.762 | BS23: 2947067 | BT23: 2681831 | BU23: 0.0040068543 | BV23: 2010 | BW23: 780 | BX23: 33008.828 | BY23: 160455 | BZ23: 193463.83 | CA23: 3770.998 | CB23: 15440.318 | CC23: 2645.53 | CD23: 43000 | CE23: 285473 | CF23: 15116071 | CG23: 46.24 | CH23: 1188180 | CI23: 121 | CJ23: 2645530 | CK23: 43000 | CL23: 285473 | CM23: 1014264 | CN23: -982761.7 | CO23: 1912731 | CP23: 0 | CQ23: 3800 | CR23: 58.78 | CS23: 71.43 | CT23: 438 | CU23: 92.06 | CV23: 3526 | CW23: 32761.03 | CX23: 62.85 | CY23: 58.78 | CZ23: 71.43 | DA23: 438 | DB23: 92.06 | DC23: 3526 | DD23: 32761.03 | DE23: 99.64 | DF23: 780.21 | DG23: 66.9 | DH23: 70.76 | DI23: 100.054 | DJ23: 99.64 | DK23: 780.21 | DL23: 260.695 | DM23: 1968 | DN23: 66.9 | DO23: 70.76 | DP23: 100.054
B24: 2 | C24: 695.7845 | D24: 3713.5 | E24: 1675 | F24: 2.2169162 | G24: 275.1785 | H24: 2005 | I24: 48.44 | J24: 674289 | K24: 122.5 | L24: 4.12 | M24: 126 | N24: 33707.419 | O24: 695.7845 | P24: 33707.419 | Q24: 197505.42 | R24: 163798 | S24: 22239.514 | T24: 0.1126 | U24: 197505.42 | V24: 111005.22 | W24: 0.00315 | X24: 35226297 | Y24: 1027.617 | Z24: 8230.5 | AA24: 3330.9885 | AB24: 1069.761 | AC24: 2076.299 | AD24: 0.0515 | AE24: 860.34525 | AF24: 1017839 | AG24: 33876.226 | AH24: 35226297 | AI24: 111005.22 | AJ24: 1069761 | AK24: 31840.172 | AL24: 8541.05 | AM24: 8230.5 | AN24: 244.36838 | AO24: 50.266132 | AP24: 3.3033041 | AQ24: 31329.039 | AR24: 325.5 | AS24: 4150 | AT24: 9052.5 | AU24: 37570200 | AV24: 2444016 | AW24: 33876.226 | AX24: 31840.172 | AY24: 2036.0548 | AZ24: 4270.5 | BA24: 7371 | BB24: 7640.5 | BC24: 3713.5 | BD24: 2010 | BE24: 7371 | BF24: 860.34525 | BG24: 590 | BH24: 590 | BI24: 7640.5 | BJ24: 4270.5 | BK24: 3156 | BL24: 860.34525 | BM24: 3277235 | BN24: 3899 | BO24: 33707.419 | BP24: 163798 | BQ24: 197505.42 | BR24: 1069.761 | BS24: 3277235 | BT24: 2814449 | BU24: 0.0028187393 | BV24: 2010 | BW24: 590 | BX24: 33707.419 | BY24: 163798 | BZ24: 197505.42 | CA24: 3892.679 | CB24: 15712.042 | CC24: 2704.965 | CD24: 45500 | CE24: 286046.5 | CF24: 16173286 | CG24: 49.73 | CH24: 1209090 | CI24: 128.5 | CJ24: 2704965 | CK24: 45500 | CL24: 286046.5 | CM24: 1017839 | CN24: -985998.83 | CO24: 1966255 | CP24: 0 | CQ24: 3900 | CR24: 59.625 | CS24: 71.685 | CT24: 456 | CU24: 92.295 | CV24: 3584.5 | CW24: 33302.535 | CX24: 60.815 | CY24: 59.625 | CZ24: 71.685 | DA24: 456 | DB24: 92.295 | DC24: 3584.5 | DD24: 33302.535 | DE24: 99.025 | DF24: 806.885 | DG24: 67.03 | DH24: 70.92 | DI24: 99.847 | DJ24: 99.025 | DK24: 806.885 | DL24: 275.1785 | DM24: 2005 | DN24: 67.03 | DO24: 70.92 | DP24: 99.847
A25: 2011 | B25: 1 | C25: 703.168 | D25: 3780 | E25: 1700 | F25: 2.2235294 | G25: 289.662 | H25: 2042 | I25: 48.93 | J25: 688401 | K25: 125 | L25: 4.23 | M25: 120 | N25: 34406.01 | O25: 703.168 | P25: 34406.01 | Q25: 201547.01 | R25: 167141 | S25: 22714.348 | T25: 0.1127 | U25: 201547.01 | V25: 115436.92 | W25: 0.0032 | X25: 36074037 | Y25: 1033.82 | Z25: 8290 | AA25: 3364.635 | AB25: 1076.76 | AC25: 2132.819 | AD25: 0.052 | AE25: 889.203 | AF25: 1021414 | AG25: 34955.742 | AH25: 36074037 | AI25: 115436.92 | AJ25: 1076760 | AK25: 32178.041 | AL25: 8694 | AM25: 8290 | AN25: 245.11599 | AO25: 50.595 | AP25: 3.3034121 | AQ25: 31502.302 | AR25: 231 | AS25: 4300 | AT25: 9068 | AU25: 38992400 | AV25: 1803701.9 | AW25: 34955.742 | AX25: 32178.041 | AY25: 2777.7008 | AZ25: 4347 | BA25: 7391 | BB25: 7890 | BC25: 3780 | BD25: 2011 | BE25: 7391 | BF25: 889.203 | BG25: 400 | BH25: 400 | BI25: 7890 | BJ25: 4347 | BK25: 3213 | BL25: 889.203 | BM25: 3607403 | BN25: 3969 | BO25: 34406.01 | BP25: 167141 | BQ25: 201547.01 | BR25: 1076.76 | BS25: 3607403 | BT25: 2947067 | BU25: 0.0016306244 | BV25: 2011 | BW25: 400 | BX25: 34406.01 | BY25: 167141 | BZ25: 201547.01 | CA25: 4014.36 | CB25: 15983.767 | CC25: 2764.4 | CD25: 48000 | CE25: 286620 | CF25: 17230500 | CG25: 53.22 | CH25: 1230000 | CI25: 136 | CJ25: 2764400 | CK25: 48000 | CL25: 286620 | CM25: 1021414 | CN25: -989235.96 | CO25: 2019779 | CP25: 0 | CQ25: 4000 | CR25: 60.47 | CS25: 71.94 | CT25: 474 | CU25: 92.53 | CV25: 3643 | CW25: 33844.04 | CX25: 58.78 | CY25: 60.47 | CZ25: 71.94 | DA25: 474 | DB25: 92.53 | DC25: 3643 | DD25: 33844.04 | DE25: 98.41 | DF25: 833.56 | DG25: 67.16 | DH25: 71.08 | DI25: 99.64 | DJ25: 98.41 | DK25: 833.56 | DL25: 289.662 | DM25: 2042 | DN25: 67.16 | DO25: 71.08 | DP25: 99.64
B26: 2 | C26: 708.7375 | D26: 3931 | E26: 1775 | F26: 2.2150079 | G26: 289.662 | H26: 2608.5 | I26: 49.33 | J26: 695784.5 | K26: 130 | L26: 4.495 | M26: 122.5 | N26: 34964.249 | O26: 708.7375 | P26: 34964.249 | Q26: 200104.75 | R26: 165140.5 | S26: 22522.006 | T26: 0.11255 | U26: 200104.75 | V26: 117166.7 | W26: 0.0032 | X26: 36614592 | Y26: 1677.2985 | Z26: 8566.5 | AA26: 3368.727 | AB26: 2201.241 | AC26: 1809.223 | AD26: 0.052 | AE26: 930.3381 | AF26: 1027617 | AG26: 35293.764 | AH26: 36614592 | AI26: 117166.7 | AJ26: 2201241 | AK26: 30802.459 | AL26: 9041.3 | AM26: 8566.5 | AN26: 246.78385 | AO26: 50.9355 | AP26: 3.30352 | AQ26: 31840.172 | AR26: 181.5 | AS26: 4350 | AT26: 9369 | AU26: 40770200 | AV26: 1442406.4 | AW26: 35293.764 | AX26: 30802.459 | AY26: 4491.3054 | AZ26: 4520.65 | BA26: 7640.5 | BB26: 8266.5 | BC26: 3931 | BD26: 2011 | BE26: 7640.5 | BF26: 930.3381 | BG26: 300 | BH26: 300 | BI26: 8266.5 | BJ26: 4520.65 | BK26: 3291 | BL26: 930.3381 | BM26: 3661458 | BN26: 4127.5 | BO26: 34964.249 | BP26: 165140.5 | BQ26: 200104.75 | BR26: 2201.241 | BS26: 3661458 | BT26: 3277235 | BU26: 0.016196507 | BV26: 2011 | BW26: 300 | BX26: 34964.249 | BY26: 165140.5 | BZ26: 200104.75 | CA26: 4107.369 | CB26: 16729.378 | CC26: 3019.2 | CD26: 46500 | CE26: 287857.5 | CF26: 18034269 | CG26: 48.12 | CH26: 1362222 | CI26: 138 | CJ26: 3019200 | CK26: 46500 | CL26: 287857.5 | CM26: 1027617 | CN26: -996814.54 | CO26: 2076299 | CP26: 0 | CQ26: 4150 | CR26: 62.62 | CS26: 71.955 | CT26: 474 | CU26: 93.045 | CV26: 3668.5 | CW26: 33893.405 | CX26: 59.625 | CY26: 62.62 | CZ26: 71.955 | DA26: 474 | DB26: 93.045 | DC26: 3668.5 | DD26: 33893.405 | DE26: 99.57 | DF26: 843.385 | DG26: 67.035 | DH26: 71.24 | DI26: 99.025 | DJ26: 99.57 | DK26: 843.385 | DL26: 289.662 | DM26: 2608.5 | DN26: 67.035 | DO26: 71.24 | DP26: 99.025
A27: 2012 | B27: 1 | C27: 714.307 | D27: 4082 | E27: 1850 | F27: 2.2064865 | G27: 289.662 | H27: 3175 | I27: 49.73 | J27: 703168 | K27: 135 | L27: 4.76 | M27: 125 | N27: 35522.487 | O27: 714.307 | P27: 35522.487 | Q27: 198662.49 | R27: 163140 | S27: 22329.664 | T27: 0.1124 | U27: 198662.49 | V27: 118896.47 | W27: 0.0032 | X27: 37155148 | Y27: 2320.777 | Z27: 8843 | AA27: 3372.819 | AB27: 3325.722 | AC27: 1485.627 | AD27: 0.052 | AE27: 971.4732 | AF27: 1033820 | AG27: 35631.787 | AH27: 37155148 | AI27: 118896.47 | AJ27: 3325722 | AK27: 29426.877 | AL27: 9388.6 | AM27: 8843 | AN27: 248.45171 | AO27: 51.276 | AP27: 3.303628 | AQ27: 32178.041 | AR27: 132 | AS27: 4400 | AT27: 9670 | AU27: 42548000 | AV27: 1081111 | AW27: 35631.787 | AX27: 29426.877 | AY27: 6204.9099 | AZ27: 4694.3 | BA27: 7890 | BB27: 8643 | BC27: 4082 | BD27: 2012 | BE27: 7890 | BF27: 971.4732 | BG27: 200 | BH27: 200 | BI27: 8643 | BJ27: 4694.3 | BK27: 3369 | BL27: 971.4732 | BM27: 3715513 | BN27: 4286 | BO27: 35522.487 | BP27: 163140 | BQ27: 198662.49 | BR27: 3325.722 | BS27: 3715513 | BT27: 3607403 | BU27: 0.03076239 | BV27: 2012 | BW27: 200 | BX27: 35522.487 | BY27: 163140 | BZ27: 198662.49 | CA27: 4200.378 | CB27: 17474.989 | CC27: 3274 | CD27: 45000 | CE27: 289095 | CF27: 18838038 | CG27: 43.02 | CH27: 1494444 | CI27: 140 | CJ27: 3274000 | CK27: 45000 | CL27: 289095 | CM27: 1033820 | CN27: -1004393.1 | CO27: 2132819 | CP27: 0 | CQ27: 4300 | CR27: 64.77 | CS27: 71.97 | CT27: 474 | CU27: 93.56 | CV27: 3694 | CW27: 33942.77 | CX27: 60.47 | CY27: 64.77 | CZ27: 71.97 | DA27: 474 | DB27: 93.56 | DC27: 3694 | DD27: 33942.77 | DE27: 100.73 | DF27: 853.21 | DG27: 66.91 | DH27: 71.4 | DI27: 98.41 | DJ27: 100.73 | DK27: 853.21 | DL27: 289.662 | DM27: 3175 | DN27: 66.91 | DO27: 71.4 | DP27: 98.41
B28: 2 | C28: 705.8255 | D28: 4352.5 | E28: 1875 | F28: 2.3198222 | G28: 281.357 | H28: 2901 | I28: 50.47 | J28: 708737.5 | K28: 151 | L28: 5.065 | M28: 130 | N28: 35616.737 | O28: 705.8255 | P28: 35616.737 | Q28: 195456.24 | R28: 159839.5 | S28: 21911.606 | T28: 0.1121 | U28: 195456.24 | V28: 117667.88 | W28: 0.003162 | X28: 37213823 | Y28: 2215.1265 | Z28: 9117 | AA28: 3402.217 | AB28: 3305.0745 | AC28: 897.177 | AD28: 0.0525 | AE28: 985.5385 | AF28: 1677298.5 | AG28: 35384.049 | AH28: 37213823 | AI28: 117667.88 | AJ28: 3305074.5 | AK28: 30069.708 | AL28: 10010.75 | AM28: 9117 | AN28: 250.12851 | AO28: 51.6155 | AP28: 3.3037359 | AQ28: 30802.459 | AR28: 195 | AS28: 4600 | AT28: 10929.5 | AU28: 50527600 | AV28: 599230.5 | AW28: 35384.049 | AX28: 30069.708 | AY28: 5314.3411 | AZ28: 4961.15 | BA28: 8266.5 | BB28: 8792 | BC28: 4352.5 | BD28: 2012 | BE28: 8266.5 | BF28: 985.5385 | BG28: 325 | BH28: 325 | BI28: 8792 | BJ28: 4961.15 | BK28: 3599 | BL28: 985.5385 | BM28: 3721596.5 | BN28: 4570 | BO28: 35616.737 | BP28: 159839.5 | BQ28: 195456.24 | BR28: 3305.0745 | BS28: 3721596.5 | BT28: 3661458 | BU28: 0.15035395 | BV28: 2012 | BW28: 325 | BX28: 35616.737 | BY28: 159839.5 | BZ28: 195456.24 | CA28: 4455.6075 | CB28: 17177.185 | CC28: 3242.75 | CD28: 50500 | CE28: 288347.5 | CF28: 18787075 | CG28: 46.76 | CH28: 1430555.5 | CI28: 160 | CJ28: 3242750 | CK28: 50500 | CL28: 288347.5 | CM28: 1677298.5 | CN28: -1647228.8 | CO28: 1809223 | CP28: 0 | CQ28: 4350 | CR28: 62.22 | CS28: 72.17 | CT28: 463 | CU28: 93.73 | CV28: 3658.5 | CW28: 33663.215 | CX28: 62.62 | CY28: 62.22 | CZ28: 72.17 | DA28: 463 | DB28: 93.73 | DC28: 3658.5 | DD28: 33663.215 | DE28: 101.155 | DF28: 858.515 | DG28: 67.04 | DH28: 71.56 | DI28: 99.57 | DJ28: 101.155 | DK28: 858.515 | DL28: 281.357 | DM28: 2901 | DN28: 67.04 | DO28: 71.56 | DP28: 99.57
A29: 2013 | B29: 1 | C29: 697.344 | D29: 4623 | E29: 1900 | F29: 2.4331579 | G29: 273.052 | H29: 2627 | I29: 51.21 | J29: 714307 | K29: 167 | L29: 5.37 | M29: 135 | N29: 35710.986 | O29: 697.344 | P29: 35710.986 | Q29: 192249.99 | R29: 156539 | S29: 21493.548 | T29: 0.1118 | U29: 192249.99 | V29: 116439.28 | W29: 0.003124 | X29: 37272498 | Y29: 2109.476 | Z29: 9391 | AA29: 3431.615 | AB29: 3284.427 | AC29: 308.727 | AD29: 0.053 | AE29: 999.6038 | AF29: 2320777 | AG29: 35136.31 | AH29: 37272498 | AI29: 116439.28 | AJ29: 3284427 | AK29: 30712.538 | AL29: 10632.9 | AM29: 9391 | AN29: 251.80531 | AO29: 51.955 | AP29: 3.3038438 | AQ29: 29426.877 | AR29: 258 | AS29: 4800 | AT29: 12189 | AU29: 58507200 | AV29: 117350 | AW29: 35136.31 | AX29: 30712.538 | AY29: 4423.7723 | AZ29: 5228 | BA29: 8643 | BB29: 8941 | BC29: 4623 | BD29: 2013 | BE29: 8643 | BF29: 999.6038 | BG29: 450 | BH29: 450 | BI29: 8941 | BJ29: 5228 | BK29: 3829 | BL29: 999.6038 | BM29: 3727680 | BN29: 4854 | BO29: 35710.986 | BP29: 156539 | BQ29: 192249.99 | BR29: 3284.427 | BS29: 3727680 | BT29: 3715513 | BU29: 0.26994551 | BV29: 2013 | BW29: 450 | BX29: 35710.986 | BY29: 156539 | BZ29: 192249.99 | CA29: 4710.837 | CB29: 16879.381 | CC29: 3211.5 | CD29: 56000 | CE29: 287600 | CF29: 18736112 | CG29: 50.5 | CH29: 1366667 | CI29: 180 | CJ29: 3211500 | CK29: 56000 | CL29: 287600 | CM29: 2320777 | CN29: -2290064.5 | CO29: 1485627 | CP29: 0 | CQ29: 4400 | CR29: 59.67 | CS29: 72.37 | CT29: 452 | CU29: 93.9 | CV29: 3623 | CW29: 33383.66 | CX29: 64.77 | CY29: 59.67 | CZ29: 72.37 | DA29: 452 | DB29: 93.9 | DC29: 3623 | DD29: 33383.66 | DE29: 101.58 | DF29: 863.82 | DG29: 67.17 | DH29: 71.72 | DI29: 100.73 | DJ29: 101.58 | DK29: 863.82 | DL29: 273.052 | DM29: 2627 | DN29: 67.17 | DO29: 71.72 | DP29: 100.73
B30: 2 | C30: 687.034 | D30: 4780.5 | E30: 1925 | F30: 2.4827328 | G30: 272.409 | H30: 2387.5 | I30: 51.395 | J30: 705825.5 | K30: 159 | L30: 5.79 | M30: 151 | N30: 35308.205 | O30: 687.034 | P30: 35308.205 | Q30: 183839.21 | R30: 148531 | S30: 20719.88 | T30: 0.11275 | U30: 183839.21 | V30: 114535.25 | W30: 0.00311295 | X30: 36791446 | Y30: 1864.6535 | Z30: 9749.5 | AA30: 3103.242 | AB30: 2743.681 | AC30: 291.862 | AD30: 0.0545 | AE30: 1047.7222 | AF30: 2215126.5 | AG30: 34706.661 | AH30: 36791446 | AI30: 114535.25 | AJ30: 2743681 | AK30: 32077.205 | AL30: 10995.15 | AM30: 9749.5 | AN30: 253.4667 | AO30: 52.295 | AP30: 3.3039516 | AQ30: 30069.708 | AR30: 263.5 | AS30: 5250 | AT30: 12314.5 | AU30: 64707600 | AV30: -422377 | AW30: 34706.661 | AX30: 32077.205 | AY30: 2629.4561 | AZ30: 5278 | BA30: 8792 | BB30: 9289.5 | BC30: 4780.5 | BD30: 2013 | BE30: 8792 | BF30: 1047.7222 | BG30: 460 | BH30: 460 | BI30: 9289.5 | BJ30: 5278 | BK30: 3963 | BL30: 1047.7222 | BM30: 3679359.5 | BN30: 5019 | BO30: 35308.205 | BP30: 148531 | BQ30: 183839.21 | BR30: 2743.681 | BS30: 3679359.5 | BT30: 3721596.5 | BU30: 0.12357524 | BV30: 2013 | BW30: 460 | BX30: 35308.205 | BY30: 148531 | BZ30: 183839.21 | CA30: 4851.5775 | CB30: 16928.81 | CC30: 3221.5 | CD30: 65000 | CE30: 318128 | CF30: 18035446 | CG30: 49.685 | CH30: 1441667 | CI30: 167.5 | CJ30: 3221500 | CK30: 65000 | CL30: 318128 | CM30: 2215126.5 | CN30: -2183049.3 | CO30: 897177 | CP30: 0 | CQ30: 4600 | CR30: 57.46 | CS30: 73.37 | CT30: 495 | CU30: 93.975 | CV30: 3557 | CW30: 35052.845 | CX30: 62.22 | CY30: 57.46 | CZ30: 73.37 | DA30: 495 | DB30: 93.975 | DC30: 3557 | DD30: 35052.845 | DE30: 103.55 | DF30: 873.87 | DG30: 67.045 | DH30: 71.88 | DI30: 101.155 | DJ30: 103.55 | DK30: 873.87 | DL30: 272.409 | DM30: 2387.5 | DN30: 67.045 | DO30: 71.88 | DP30: 101.155
